<?xml version="1.0" ?>
<!-- =================================================================================== -->
<!-- |    This document was autogenerated by xacro from fishbot.urdf.xacro             | -->
<!-- |    EDITING THIS FILE BY HAND IS NOT RECOMMENDED                                 | -->
<!-- =================================================================================== -->
<robot name="fishbot">
  <link name="base_link">
    <visual>
      <origin rpy="0 0 0" xyz="0 0 0"/>
      <geometry>
        <cylinder length="0.12" radius="0.1"/>
      </geometry>
      <material name="white">
        <color rgba="1.0 1.0 1.0 0.5"/>
      </material>
    </visual>
    <collision>
      <origin rpy="0 0 0" xyz="0 0 0"/>
      <geometry>
        <cylinder length="0.12" radius="0.1"/>
      </geometry>
    </collision>
    <inertial>
      <mass value="1.0"/>
      <inertia ixx="0.0037000000000000006" ixy="0.0" ixz="0.0" iyy="0.0037000000000000006" iyz="0.0" izz="0.005000000000000001"/>
    </inertial>
  </link>
  <link name="imu_link">
    <visual>
      <origin rpy="0 0 0" xyz="0 0 0"/>
      <geometry>
        <box size="0.02 0.02 0.02"/>
      </geometry>
      <material name="black">
        <color rgba="0 0 0.8"/>
      </material>
    </visual>
    <collision>
      <origin rpy="0 0 0" xyz="0 0 0"/>
      <geometry>
        <box size="0.02 0.02 0.02"/>
      </geometry>
      <material name="black">
        <color rgba="0 0 0.8"/>
      </material>
    </collision>
    <inertial>
      <mass value="0.05"/>
      <inertia ixx="3.3333333333333333e-06" ixy="0.0" ixz="0.0" iyy="3.3333333333333333e-06" iyz="0.0" izz="3.3333333333333333e-06"/>
    </inertial>
  </link>
  <joint name="imu_joint" type="fixed">
    <parent link="base_link"/>
    <child link="imu_link"/>
    <origin xyz="0 0 0.02"/>
  </joint>
  <link name="camera_link">
    <visual>
      <origin rpy="0 0 0" xyz="0 0 0"/>
      <geometry>
        <box size="0.02 0.01 0.02"/>
      </geometry>
      <material name="green">
        <color rgba="0 1.0 0 0.8"/>
      </material>
    </visual>
    <collision>
      <origin rpy="0 0 0" xyz="0 0 0"/>
      <geometry>
        <box size="0.02 0.01 0.02"/>
      </geometry>
      <material name="green">
        <color rgba="0 1.0 0 0.8"/>
      </material>
    </collision>
    <inertial>
      <mass value="0.1"/>
      <inertia ixx="4.166666666666667e-06" ixy="0.0" ixz="0.0" iyy="6.666666666666667e-06" iyz="0.0" izz="4.166666666666667e-06"/>
    </inertial>
  </link>
  <joint name="camera_joint" type="fixed">
    <parent link="base_link"/>
    <child link="camera_link"/>
    <origin xyz="0.1 0 0.075"/>
  </joint>
  <link name="laser_cylinder_link">
    <visual>
      <origin rpy="0 0 0" xyz="0 0 0"/>
      <geometry>
        <cylinder length="0.1" radius="0.01"/>
      </geometry>
      <material name="green">
        <color rgba="0 1.0 0 0.8"/>
      </material>
    </visual>
    <collision>
      <origin rpy="0 0 0" xyz="0 0 0"/>
      <geometry>
        <cylinder length="0.1" radius="0.01"/>
      </geometry>
      <material name="green">
        <color rgba="0 1.0 0 0.8"/>
      </material>
    </collision>
    <inertial>
      <mass value="0.05"/>
      <inertia ixx="4.2916666666666675e-05" ixy="0.0" ixz="0.0" iyy="4.2916666666666675e-05" iyz="0.0" izz="2.5e-06"/>
    </inertial>
  </link>
  <joint name="laser_cylinder_joint" type="fixed">
    <parent link="base_link"/>
    <child link="laser_cylinder_link"/>
    <origin xyz="0 0 0.1"/>
  </joint>
  <link name="laser_link">
    <visual>
      <origin rpy="0 0 0" xyz="0 0 0"/>
      <geometry>
        <cylinder length="0.02" radius="0.02"/>
      </geometry>
      <material name="green">
        <color rgba="0 1.0 0 0.8"/>
      </material>
    </visual>
    <collision>
      <origin rpy="0 0 0" xyz="0 0 0"/>
      <geometry>
        <cylinder length="0.02" radius="0.02"/>
      </geometry>
      <material name="green">
        <color rgba="0 1.0 0 0.8"/>
      </material>
    </collision>
    <inertial>
      <mass value="0.1"/>
      <inertia ixx="1.3333333333333332e-05" ixy="0.0" ixz="0.0" iyy="1.3333333333333332e-05" iyz="0.0" izz="2e-05"/>
    </inertial>
  </link>
  <joint name="laser_joint" type="fixed">
    <parent link="laser_cylinder_link"/>
    <child link="laser_link"/>
    <origin xyz="0 0 0.05"/>
  </joint>
  <link name="left_wheel_wheel_link">
    <visual>
      <origin rpy="1.57079 0 0" xyz="0 0 0"/>
      <geometry>
        <cylinder length="0.04" radius="0.032"/>
      </geometry>
      <material name="yellow">
        <color rgba="1.0 1.0 0 0.8"/>
      </material>
    </visual>
    <collision>
      <origin rpy="1.57079 0 0" xyz="0 0 0"/>
      <geometry>
        <cylinder length="0.04" radius="0.032"/>
      </geometry>
      <material name="yellow">
        <color rgba="1.0 1.0 0 0.8"/>
      </material>
    </collision>
    <inertial>
      <mass value="0.05"/>
      <inertia ixx="1.9466666666666668e-05" ixy="0.0" ixz="0.0" iyy="1.9466666666666668e-05" iyz="0.0" izz="2.5600000000000002e-05"/>
    </inertial>
  </link>
  <joint name="left_wheel_wheel_joint" type="continuous">
    <parent link="base_link"/>
    <child link="left_wheel_wheel_link"/>
    <origin xyz="0 0.10 -0.06"/>
    <axis xyz="0 1 0"/>
  </joint>
  <link name="right_wheel_wheel_link">
    <visual>
      <origin rpy="1.57079 0 0" xyz="0 0 0"/>
      <geometry>
        <cylinder length="0.04" radius="0.032"/>
      </geometry>
      <material name="yellow">
        <color rgba="1.0 1.0 0 0.8"/>
      </material>
    </visual>
    <collision>
      <origin rpy="1.57079 0 0" xyz="0 0 0"/>
      <geometry>
        <cylinder length="0.04" radius="0.032"/>
      </geometry>
      <material name="yellow">
        <color rgba="1.0 1.0 0 0.8"/>
      </material>
    </collision>
    <inertial>
      <mass value="0.05"/>
      <inertia ixx="1.9466666666666668e-05" ixy="0.0" ixz="0.0" iyy="1.9466666666666668e-05" iyz="0.0" izz="2.5600000000000002e-05"/>
    </inertial>
  </link>
  <joint name="right_wheel_wheel_joint" type="continuous">
    <parent link="base_link"/>
    <child link="right_wheel_wheel_link"/>
    <origin xyz="0 -0.10 -0.06"/>
    <axis xyz="0 1 0"/>
  </joint>
  <link name="front_caster_caster_link">
    <visual>
      <origin rpy="0 0 0" xyz="0 0 0"/>
      <geometry>
        <sphere radius="0.016"/>
      </geometry>
      <material name="yellow">
        <color rgba="1.0 1.0 0.0 0.8"/>
      </material>
    </visual>
    <collision>
      <origin rpy="0 0 0" xyz="0 0 0"/>
      <geometry>
        <sphere radius="0.016"/>
      </geometry>
      <material name="yellow">
        <color rgba="1.0 1.0 0.0 0.8"/>
      </material>
    </collision>
    <inertial>
      <mass value="0.05"/>
      <inertia ixx="5.120000000000002e-06" ixy="0.0" ixz="0.0" iyy="5.120000000000002e-06" iyz="0.0" izz="5.120000000000002e-06"/>
    </inertial>
  </link>
  <joint name="front_caster_caster_joint" type="fixed">
    <parent link="base_link"/>
    <child link="front_caster_caster_link"/>
    <origin xyz="0.08 0.0 -0.076"/>
    <axis xyz="0 0 0"/>
  </joint>
  <link name="back_caster_caster_link">
    <visual>
      <origin rpy="0 0 0" xyz="0 0 0"/>
      <geometry>
        <sphere radius="0.016"/>
      </geometry>
      <material name="yellow">
        <color rgba="1.0 1.0 0.0 0.8"/>
      </material>
    </visual>
    <collision>
      <origin rpy="0 0 0" xyz="0 0 0"/>
      <geometry>
        <sphere radius="0.016"/>
      </geometry>
      <material name="yellow">
        <color rgba="1.0 1.0 0.0 0.8"/>
      </material>
    </collision>
    <inertial>
      <mass value="0.05"/>
      <inertia ixx="5.120000000000002e-06" ixy="0.0" ixz="0.0" iyy="5.120000000000002e-06" iyz="0.0" izz="5.120000000000002e-06"/>
    </inertial>
  </link>
  <joint name="back_caster_caster_joint" type="fixed">
    <parent link="base_link"/>
    <child link="back_caster_caster_link"/>
    <origin xyz="-0.08 0.0 -0.076"/>
    <axis xyz="0 0 0"/>
  </joint>
</robot>
