<?xml version="1.0"?>
<robot xmlns:xacro="http://www.ros.org/wiki/xacro">
    <xacro:include filename="$(find fishbot_description)/urdf/fishbot/common_inertia.xacro" />
    <!-- 轮子宏定义 -->
    <xacro:macro name="wheel_xacro" params="wheel_name xyz">
        <link name="${wheel_name}_wheel_link">
            <visual>
                <origin xyz="0 0 0" rpy="1.57079 0 0" />
                <geometry>
                    <cylinder radius="0.032" length="0.04"/>
                </geometry>
                <material name="yellow">
                    <color rgba="1.0 1.0 0 0.8" />
                </material>
            </visual>

            <collision>
                <origin xyz="0 0 0" rpy="1.57079 0 0" />
                <geometry>
                    <cylinder radius="0.032" length="0.04"/>
                </geometry>
                <material name="yellow">
                    <color rgba="1.0 1.0 0 0.8" />
                </material>
            </collision>

            <inertial>
                <xacro:cylinder_inertia m="0.05" r="0.032" h="0.04" />
            </inertial>
        </link>

        <joint name="${wheel_name}_wheel_joint" type="continuous">
            <parent link="base_link"/>
            <child link="${wheel_name}_wheel_link"/>
            <origin xyz="${xyz}" rpy="0 0 0" />
            <axis xyz="0 1 0"/>

            <limit effort="100" velocity="100" />
            <dynamics damping="0.1" friction="0.1" />
        </joint>

        <!-- 轮子物理属性配置-->
        <gazebo reference="${wheel_name}_wheel_link">
            <mu1>20.0</mu1>
            <mu2>20.0</mu2>
            <kp>1000000000.0</kp>
            <kd>1.0</kd>
        </gazebo>

    </xacro:macro>
</robot>
